Workbook

Sheet 정산
B1: 🍺 술자리 N차 정산표
B2: 노란 칸(파란 글씨)만 입력하세요 → ① 아래 [참여 체크]에 이름 입력 ② [차수별 결제]에 금액·결제자 선택 ③ 참여한 차수에 O 선택. 나머지는 자동 계산됩니다.
B3: ※ 예시 데이터가 들어 있습니다. 지우고 새로 입력하면 됩니다. (최대 6차 / 12명)
B5: 1. 차수별 결제
B6: 차수 | C6: 장소/메모 | D6: 총 금액 | E6: 결제한 사람 | F6: 참여 인원 | G6: 1인당 금액
B7: 1차 | C7: 삼겹살집 | D7: 120000 | E7: 민수 | F7: =COUNTIF(C$17:C$28,"O") -> 4 | G7: =IF(F7=0,0,D7/F7) -> 30000
B8: 2차 | C8: 호프집 | D8: 85000 | E8: 지영 | F8: =COUNTIF(D$17:D$28,"O") -> 4 | G8: =IF(F8=0,0,D8/F8) -> 21250
B9: 3차 | C9: 노래방 | D9: 40000 | E9: 민수 | F9: =COUNTIF(E$17:E$28,"O") -> 4 | G9: =IF(F9=0,0,D9/F9) -> 10000
B10: 4차 | F10: =COUNTIF(F$17:F$28,"O") -> 0 | G10: =IF(F10=0,0,D10/F10) -> 0
B11: 5차 | F11: =COUNTIF(G$17:G$28,"O") -> 0 | G11: =IF(F11=0,0,D11/F11) -> 0
B12: 6차 | F12: =COUNTIF(H$17:H$28,"O") -> 0 | G12: =IF(F12=0,0,D12/F12) -> 0
B13: 합계 | D13: =SUM(D7:D12) -> 245000
B15: 2. 참여 체크 & 개인별 정산
B16: 이름 | C16: 1차 | D16: 2차 | E16: 3차 | F16: 4차 | G16: 5차 | H16: 6차 | I16: 내야 할 돈 | J16: 이미 낸 돈 | K16: 차액 (+받음/-보냄) | L16: 결과
B17: 민수 | C17: O | D17: O | E17: O | I17: =IF(C17="O",$G$7,0)+IF(D17="O",$G$8,0)+IF(E17="O",$G$9,0)+IF(F17="O",$G$10,0)+IF(G17="O",$G$11,0)+IF(H17="O",$G$12,0) -> 61250 | J17: =IF(B17="",0,SUMIF($E$7:$E$12,B17,$D$7:$D$12)) -> 160000 | K17: =J17-I17 -> 98750 | L17: =IF(B17="","",IF(K17>=1,"받을 돈 있음",IF(K17<=-1,"보내야 함","정산 끝"))) -> 받을 돈 있음
B18: 지영 | C18: O | D18: O | E18: O | I18: =IF(C18="O",$G$7,0)+IF(D18="O",$G$8,0)+IF(E18="O",$G$9,0)+IF(F18="O",$G$10,0)+IF(G18="O",$G$11,0)+IF(H18="O",$G$12,0) -> 61250 | J18: =IF(B18="",0,SUMIF($E$7:$E$12,B18,$D$7:$D$12)) -> 85000 | K18: =J18-I18 -> 23750 | L18: =IF(B18="","",IF(K18>=1,"받을 돈 있음",IF(K18<=-1,"보내야 함","정산 끝"))) -> 받을 돈 있음
B19: 철수 | C19: O | D19: O | I19: =IF(C19="O",$G$7,0)+IF(D19="O",$G$8,0)+IF(E19="O",$G$9,0)+IF(F19="O",$G$10,0)+IF(G19="O",$G$11,0)+IF(H19="O",$G$12,0) -> 51250 | J19: =IF(B19="",0,SUMIF($E$7:$E$12,B19,$D$7:$D$12)) -> 0 | K19: =J19-I19 -> -51250 | L19: =IF(B19="","",IF(K19>=1,"받을 돈 있음",IF(K19<=-1,"보내야 함","정산 끝"))) -> 보내야 함
B20: 영희 | C20: O | E20: O | I20: =IF(C20="O",$G$7,0)+IF(D20="O",$G$8,0)+IF(E20="O",$G$9,0)+IF(F20="O",$G$10,0)+IF(G20="O",$G$11,0)+IF(H20="O",$G$12,0) -> 40000 | J20: =IF(B20="",0,SUMIF($E$7:$E$12,B20,$D$7:$D$12)) -> 0 | K20: =J20-I20 -> -40000 | L20: =IF(B20="","",IF(K20>=1,"받을 돈 있음",IF(K20<=-1,"보내야 함","정산 끝"))) -> 보내야 함
B21: 준호 | D21: O | E21: O | I21: =IF(C21="O",$G$7,0)+IF(D21="O",$G$8,0)+IF(E21="O",$G$9,0)+IF(F21="O",$G$10,0)+IF(G21="O",$G$11,0)+IF(H21="O",$G$12,0) -> 31250 | J21: =IF(B21="",0,SUMIF($E$7:$E$12,B21,$D$7:$D$12)) -> 0 | K21: =J21-I21 -> -31250 | L21: =IF(B21="","",IF(K21>=1,"받을 돈 있음",IF(K21<=-1,"보내야 함","정산 끝"))) -> 보내야 함
I22: =IF(C22="O",$G$7,0)+IF(D22="O",$G$8,0)+IF(E22="O",$G$9,0)+IF(F22="O",$G$10,0)+IF(G22="O",$G$11,0)+IF(H22="O",$G$12,0) -> 0 | J22: =IF(B22="",0,SUMIF($E$7:$E$12,B22,$D$7:$D$12)) -> 0 | K22: =J22-I22 -> 0 | L22: =IF(B22="","",IF(K22>=1,"받을 돈 있음",IF(K22<=-1,"보내야 함","정산 끝")))
I23: =IF(C23="O",$G$7,0)+IF(D23="O",$G$8,0)+IF(E23="O",$G$9,0)+IF(F23="O",$G$10,0)+IF(G23="O",$G$11,0)+IF(H23="O",$G$12,0) -> 0 | J23: =IF(B23="",0,SUMIF($E$7:$E$12,B23,$D$7:$D$12)) -> 0 | K23: =J23-I23 -> 0 | L23: =IF(B23="","",IF(K23>=1,"받을 돈 있음",IF(K23<=-1,"보내야 함","정산 끝")))
I24: =IF(C24="O",$G$7,0)+IF(D24="O",$G$8,0)+IF(E24="O",$G$9,0)+IF(F24="O",$G$10,0)+IF(G24="O",$G$11,0)+IF(H24="O",$G$12,0) -> 0 | J24: =IF(B24="",0,SUMIF($E$7:$E$12,B24,$D$7:$D$12)) -> 0 | K24: =J24-I24 -> 0 | L24: =IF(B24="","",IF(K24>=1,"받을 돈 있음",IF(K24<=-1,"보내야 함","정산 끝")))
I25: =IF(C25="O",$G$7,0)+IF(D25="O",$G$8,0)+IF(E25="O",$G$9,0)+IF(F25="O",$G$10,0)+IF(G25="O",$G$11,0)+IF(H25="O",$G$12,0) -> 0 | J25: =IF(B25="",0,SUMIF($E$7:$E$12,B25,$D$7:$D$12)) -> 0 | K25: =J25-I25 -> 0 | L25: =IF(B25="","",IF(K25>=1,"받을 돈 있음",IF(K25<=-1,"보내야 함","정산 끝")))
I26: =IF(C26="O",$G$7,0)+IF(D26="O",$G$8,0)+IF(E26="O",$G$9,0)+IF(F26="O",$G$10,0)+IF(G26="O",$G$11,0)+IF(H26="O",$G$12,0) -> 0 | J26: =IF(B26="",0,SUMIF($E$7:$E$12,B26,$D$7:$D$12)) -> 0 | K26: =J26-I26 -> 0 | L26: =IF(B26="","",IF(K26>=1,"받을 돈 있음",IF(K26<=-1,"보내야 함","정산 끝")))
I27: =IF(C27="O",$G$7,0)+IF(D27="O",$G$8,0)+IF(E27="O",$G$9,0)+IF(F27="O",$G$10,0)+IF(G27="O",$G$11,0)+IF(H27="O",$G$12,0) -> 0 | J27: =IF(B27="",0,SUMIF($E$7:$E$12,B27,$D$7:$D$12)) -> 0 | K27: =J27-I27 -> 0 | L27: =IF(B27="","",IF(K27>=1,"받을 돈 있음",IF(K27<=-1,"보내야 함","정산 끝")))
I28: =IF(C28="O",$G$7,0)+IF(D28="O",$G$8,0)+IF(E28="O",$G$9,0)+IF(F28="O",$G$10,0)+IF(G28="O",$G$11,0)+IF(H28="O",$G$12,0) -> 0 | J28: =IF(B28="",0,SUMIF($E$7:$E$12,B28,$D$7:$D$12)) -> 0 | K28: =J28-I28 -> 0 | L28: =IF(B28="","",IF(K28>=1,"받을 돈 있음",IF(K28<=-1,"보내야 함","정산 끝")))
B29: 합계 | I29: =SUM(I17:I28) -> 245000 | J29: =SUM(J17:J28) -> 245000 | K29: =SUM(K17:K28) -> 0 | L29: =IF(ABS(I29-D13)<1,"✔ 금액 일치","⚠ 참여자 없는 차수 확인") -> ✔ 금액 일치
B31: 3. 누가 누구에게 얼마 보내면 되나요? (행 → 열로 송금, 서로 갚을 돈은 상계됨)
B32: 보내는 사람 ↓ / 받는 사람 → | C32: =IF(B17="","",B17) -> 민수 | D32: =IF(B18="","",B18) -> 지영 | E32: =IF(B19="","",B19) -> 철수 | F32: =IF(B20="","",B20) -> 영희 | G32: =IF(B21="","",B21) -> 준호 | H32: =IF(B22="","",B22) | I32: =IF(B23="","",B23) | J32: =IF(B24="","",B24) | K32: =IF(B25="","",B25) | L32: =IF(B26="","",B26) | M32: =IF(B27="","",B27) | N32: =IF(B28="","",B28) | O32: 총 보낼 돈
B33: =IF(B17="","",B17) -> 민수 | C33: =MAX(0,'계산(자동)'!B3-'계산(자동)'!B3) -> 0 | D33: =MAX(0,'계산(자동)'!C3-'계산(자동)'!B4) -> 0 | E33: =MAX(0,'계산(자동)'!D3-'계산(자동)'!B5) -> 0 | F33: =MAX(0,'계산(자동)'!E3-'계산(자동)'!B6) -> 0 | G33: =MAX(0,'계산(자동)'!F3-'계산(자동)'!B7) -> 0 | H33: =MAX(0,'계산(자동)'!G3-'계산(자동)'!B8) -> 0 | I33: =MAX(0,'계산(자동)'!H3-'계산(자동)'!B9) -> 0 | J33: =MAX(0,'계산(자동)'!I3-'계산(자동)'!B10) -> 0 | K33: =MAX(0,'계산(자동)'!J3-'계산(자동)'!B11) -> 0 | L33: =MAX(0,'계산(자동)'!K3-'계산(자동)'!B12) -> 0 | M33: =MAX(0,'계산(자동)'!L3-'계산(자동)'!B13) -> 0 | N33: =MAX(0,'계산(자동)'!M3-'계산(자동)'!B14) -> 0 | O33: =SUM(C33:N33) -> 0
B34: =IF(B18="","",B18) -> 지영 | C34: =MAX(0,'계산(자동)'!B4-'계산(자동)'!C3) -> 18750 | D34: =MAX(0,'계산(자동)'!C4-'계산(자동)'!C4) -> 0 | E34: =MAX(0,'계산(자동)'!D4-'계산(자동)'!C5) -> 0 | F34: =MAX(0,'계산(자동)'!E4-'계산(자동)'!C6) -> 0 | G34: =MAX(0,'계산(자동)'!F4-'계산(자동)'!C7) -> 0 | H34: =MAX(0,'계산(자동)'!G4-'계산(자동)'!C8) -> 0 | I34: =MAX(0,'계산(자동)'!H4-'계산(자동)'!C9) -> 0 | J34: =MAX(0,'계산(자동)'!I4-'계산(자동)'!C10) -> 0 | K34: =MAX(0,'계산(자동)'!J4-'계산(자동)'!C11) -> 0 | L34: =MAX(0,'계산(자동)'!K4-'계산(자동)'!C12) -> 0 | M34: =MAX(0,'계산(자동)'!L4-'계산(자동)'!C13) -> 0 | N34: =MAX(0,'계산(자동)'!M4-'계산(자동)'!C14) -> 0 | O34: =SUM(C34:N34) -> 18750
B35: =IF(B19="","",B19) -> 철수 | C35: =MAX(0,'계산(자동)'!B5-'계산(자동)'!D3) -> 30000 | D35: =MAX(0,'계산(자동)'!C5-'계산(자동)'!D4) -> 21250 | E35: =MAX(0,'계산(자동)'!D5-'계산(자동)'!D5) -> 0 | F35: =MAX(0,'계산(자동)'!E5-'계산(자동)'!D6) -> 0 | G35: =MAX(0,'계산(자동)'!F5-'계산(자동)'!D7) -> 0 | H35: =MAX(0,'계산(자동)'!G5-'계산(자동)'!D8) -> 0 | I35: =MAX(0,'계산(자동)'!H5-'계산(자동)'!D9) -> 0 | J35: =MAX(0,'계산(자동)'!I5-'계산(자동)'!D10) -> 0 | K35: =MAX(0,'계산(자동)'!J5-'계산(자동)'!D11) -> 0 | L35: =MAX(0,'계산(자동)'!K5-'계산(자동)'!D12) -> 0 | M35: =MAX(0,'계산(자동)'!L5-'계산(자동)'!D13) -> 0 | N35: =MAX(0,'계산(자동)'!M5-'계산(자동)'!D14) -> 0 | O35: =SUM(C35:N35) -> 51250
B36: =IF(B20="","",B20) -> 영희 | C36: =MAX(0,'계산(자동)'!B6-'계산(자동)'!E3) -> 40000 | D36: =MAX(0,'계산(자동)'!C6-'계산(자동)'!E4) -> 0 | E36: =MAX(0,'계산(자동)'!D6-'계산(자동)'!E5) -> 0 | F36: =MAX(0,'계산(자동)'!E6-'계산(자동)'!E6) -> 0 | G36: =MAX(0,'계산(자동)'!F6-'계산(자동)'!E7) -> 0 | H36: =MAX(0,'계산(자동)'!G6-'계산(자동)'!E8) -> 0 | I36: =MAX(0,'계산(자동)'!H6-'계산(자동)'!E9) -> 0 | J36: =MAX(0,'계산(자동)'!I6-'계산(자동)'!E10) -> 0 | K36: =MAX(0,'계산(자동)'!J6-'계산(자동)'!E11) -> 0 | L36: =MAX(0,'계산(자동)'!K6-'계산(자동)'!E12) -> 0 | M36: =MAX(0,'계산(자동)'!L6-'계산(자동)'!E13) -> 0 | N36: =MAX(0,'계산(자동)'!M6-'계산(자동)'!E14) -> 0 | O36: =SUM(C36:N36) -> 40000
B37: =IF(B21="","",B21) -> 준호 | C37: =MAX(0,'계산(자동)'!B7-'계산(자동)'!F3) -> 10000 | D37: =MAX(0,'계산(자동)'!C7-'계산(자동)'!F4) -> 21250 | E37: =MAX(0,'계산(자동)'!D7-'계산(자동)'!F5) -> 0 | F37: =MAX(0,'계산(자동)'!E7-'계산(자동)'!F6) -> 0 | G37: =MAX(0,'계산(자동)'!F7-'계산(자동)'!F7) -> 0 | H37: =MAX(0,'계산(자동)'!G7-'계산(자동)'!F8) -> 0 | I37: =MAX(0,'계산(자동)'!H7-'계산(자동)'!F9) -> 0 | J37: =MAX(0,'계산(자동)'!I7-'계산(자동)'!F10) -> 0 | K37: =MAX(0,'계산(자동)'!J7-'계산(자동)'!F11) -> 0 | L37: =MAX(0,'계산(자동)'!K7-'계산(자동)'!F12) -> 0 | M37: =MAX(0,'계산(자동)'!L7-'계산(자동)'!F13) -> 0 | N37: =MAX(0,'계산(자동)'!M7-'계산(자동)'!F14) -> 0 | O37: =SUM(C37:N37) -> 31250
B38: =IF(B22="","",B22) | C38: =MAX(0,'계산(자동)'!B8-'계산(자동)'!G3) -> 0 | D38: =MAX(0,'계산(자동)'!C8-'계산(자동)'!G4) -> 0 | E38: =MAX(0,'계산(자동)'!D8-'계산(자동)'!G5) -> 0 | F38: =MAX(0,'계산(자동)'!E8-'계산(자동)'!G6) -> 0 | G38: =MAX(0,'계산(자동)'!F8-'계산(자동)'!G7) -> 0 | H38: =MAX(0,'계산(자동)'!G8-'계산(자동)'!G8) -> 0 | I38: =MAX(0,'계산(자동)'!H8-'계산(자동)'!G9) -> 0 | J38: =MAX(0,'계산(자동)'!I8-'계산(자동)'!G10) -> 0 | K38: =MAX(0,'계산(자동)'!J8-'계산(자동)'!G11) -> 0 | L38: =MAX(0,'계산(자동)'!K8-'계산(자동)'!G12) -> 0 | M38: =MAX(0,'계산(자동)'!L8-'계산(자동)'!G13) -> 0 | N38: =MAX(0,'계산(자동)'!M8-'계산(자동)'!G14) -> 0 | O38: =SUM(C38:N38) -> 0
B39: =IF(B23="","",B23) | C39: =MAX(0,'계산(자동)'!B9-'계산(자동)'!H3) -> 0 | D39: =MAX(0,'계산(자동)'!C9-'계산(자동)'!H4) -> 0 | E39: =MAX(0,'계산(자동)'!D9-'계산(자동)'!H5) -> 0 | F39: =MAX(0,'계산(자동)'!E9-'계산(자동)'!H6) -> 0 | G39: =MAX(0,'계산(자동)'!F9-'계산(자동)'!H7) -> 0 | H39: =MAX(0,'계산(자동)'!G9-'계산(자동)'!H8) -> 0 | I39: =MAX(0,'계산(자동)'!H9-'계산(자동)'!H9) -> 0 | J39: =MAX(0,'계산(자동)'!I9-'계산(자동)'!H10) -> 0 | K39: =MAX(0,'계산(자동)'!J9-'계산(자동)'!H11) -> 0 | L39: =MAX(0,'계산(자동)'!K9-'계산(자동)'!H12) -> 0 | M39: =MAX(0,'계산(자동)'!L9-'계산(자동)'!H13) -> 0 | N39: =MAX(0,'계산(자동)'!M9-'계산(자동)'!H14) -> 0 | O39: =SUM(C39:N39) -> 0
B40: =IF(B24="","",B24) | C40: =MAX(0,'계산(자동)'!B10-'계산(자동)'!I3) -> 0 | D40: =MAX(0,'계산(자동)'!C10-'계산(자동)'!I4) -> 0 | E40: =MAX(0,'계산(자동)'!D10-'계산(자동)'!I5) -> 0 | F40: =MAX(0,'계산(자동)'!E10-'계산(자동)'!I6) -> 0 | G40: =MAX(0,'계산(자동)'!F10-'계산(자동)'!I7) -> 0 | H40: =MAX(0,'계산(자동)'!G10-'계산(자동)'!I8) -> 0 | I40: =MAX(0,'계산(자동)'!H10-'계산(자동)'!I9) -> 0 | J40: =MAX(0,'계산(자동)'!I10-'계산(자동)'!I10) -> 0 | K40: =MAX(0,'계산(자동)'!J10-'계산(자동)'!I11) -> 0 | L40: =MAX(0,'계산(자동)'!K10-'계산(자동)'!I12) -> 0 | M40: =MAX(0,'계산(자동)'!L10-'계산(자동)'!I13) -> 0 | N40: =MAX(0,'계산(자동)'!M10-'계산(자동)'!I14) -> 0 | O40: =SUM(C40:N40) -> 0
B41: =IF(B25="","",B25) | C41: =MAX(0,'계산(자동)'!B11-'계산(자동)'!J3) -> 0 | D41: =MAX(0,'계산(자동)'!C11-'계산(자동)'!J4) -> 0 | E41: =MAX(0,'계산(자동)'!D11-'계산(자동)'!J5) -> 0 | F41: =MAX(0,'계산(자동)'!E11-'계산(자동)'!J6) -> 0 | G41: =MAX(0,'계산(자동)'!F11-'계산(자동)'!J7) -> 0 | H41: =MAX(0,'계산(자동)'!G11-'계산(자동)'!J8) -> 0 | I41: =MAX(0,'계산(자동)'!H11-'계산(자동)'!J9) -> 0 | J41: =MAX(0,'계산(자동)'!I11-'계산(자동)'!J10) -> 0 | K41: =MAX(0,'계산(자동)'!J11-'계산(자동)'!J11) -> 0 | L41: =MAX(0,'계산(자동)'!K11-'계산(자동)'!J12) -> 0 | M41: =MAX(0,'계산(자동)'!L11-'계산(자동)'!J13) -> 0 | N41: =MAX(0,'계산(자동)'!M11-'계산(자동)'!J14) -> 0 | O41: =SUM(C41:N41) -> 0
B42: =IF(B26="","",B26) | C42: =MAX(0,'계산(자동)'!B12-'계산(자동)'!K3) -> 0 | D42: =MAX(0,'계산(자동)'!C12-'계산(자동)'!K4) -> 0 | E42: =MAX(0,'계산(자동)'!D12-'계산(자동)'!K5) -> 0 | F42: =MAX(0,'계산(자동)'!E12-'계산(자동)'!K6) -> 0 | G42: =MAX(0,'계산(자동)'!F12-'계산(자동)'!K7) -> 0 | H42: =MAX(0,'계산(자동)'!G12-'계산(자동)'!K8) -> 0 | I42: =MAX(0,'계산(자동)'!H12-'계산(자동)'!K9) -> 0 | J42: =MAX(0,'계산(자동)'!I12-'계산(자동)'!K10) -> 0 | K42: =MAX(0,'계산(자동)'!J12-'계산(자동)'!K11) -> 0 | L42: =MAX(0,'계산(자동)'!K12-'계산(자동)'!K12) -> 0 | M42: =MAX(0,'계산(자동)'!L12-'계산(자동)'!K13) -> 0 | N42: =MAX(0,'계산(자동)'!M12-'계산(자동)'!K14) -> 0 | O42: =SUM(C42:N42) -> 0
B43: =IF(B27="","",B27) | C43: =MAX(0,'계산(자동)'!B13-'계산(자동)'!L3) -> 0 | D43: =MAX(0,'계산(자동)'!C13-'계산(자동)'!L4) -> 0 | E43: =MAX(0,'계산(자동)'!D13-'계산(자동)'!L5) -> 0 | F43: =MAX(0,'계산(자동)'!E13-'계산(자동)'!L6) -> 0 | G43: =MAX(0,'계산(자동)'!F13-'계산(자동)'!L7) -> 0 | H43: =MAX(0,'계산(자동)'!G13-'계산(자동)'!L8) -> 0 | I43: =MAX(0,'계산(자동)'!H13-'계산(자동)'!L9) -> 0 | J43: =MAX(0,'계산(자동)'!I13-'계산(자동)'!L10) -> 0 | K43: =MAX(0,'계산(자동)'!J13-'계산(자동)'!L11) -> 0 | L43: =MAX(0,'계산(자동)'!K13-'계산(자동)'!L12) -> 0 | M43: =MAX(0,'계산(자동)'!L13-'계산(자동)'!L13) -> 0 | N43: =MAX(0,'계산(자동)'!M13-'계산(자동)'!L14) -> 0 | O43: =SUM(C43:N43) -> 0
...

Sheet 계산(자동)
A1: X(행)가 Y(열)에게 갚을 금액 (상계 전) — 수정하지 마세요
B2: =정산!B17 -> 민수 | C2: =정산!B18 -> 지영 | D2: =정산!B19 -> 철수 | E2: =정산!B20 -> 영희 | F2: =정산!B21 -> 준호 | G2: =정산!B22 -> 0 | H2: =정산!B23 -> 0 | I2: =정산!B24 -> 0 | J2: =정산!B25 -> 0 | K2: =정산!B26 -> 0 | L2: =정산!B27 -> 0 | M2: =정산!B28 -> 0
A3: =정산!B17 -> 민수 | B3: =IF(OR($A3=0,B$2=0,$A3=B$2),0,(정산!$E$7=B$2)*(정산!$C$17="O")*정산!$G$7+(정산!$E$8=B$2)*(정산!$D$17="O")*정산!$G$8+(정산!$E$9=B$2)*(정산!$E$17="O")*정산!$G$9+(정산!$E$10=B$2)*(정산!$F$17="O")*정산!$G$10+(정산!$E$11=B$2)*(정산!$G$17="O")*정산!$G$11+(정산!$E$12=B$2)*(정산!$H$17="O")*정산!$G$12) -> 0 | C3: =IF(OR($A3=0,C$2=0,$A3=C$2),0,(정산!$E$7=C$2)*(정산!$C$17="O")*정산!$G$7+(정산!$E$8=C$2)*(정산!$D$17="O")*정산!$G$8+(정산!$E$9=C$2)*(정산!$E$17="O")*정산!$G$9+(정산!$E$10=C$2)*(정산!$F$17="O")*정산!$G$10+(정산!$E$11=C$2)*(정산!$G$17="O")*정산!$G$11+(정산!$E$12=C$2)*(정산!$H$17="O")*정산!$G$12) -> 21250 | D3: =IF(OR($A3=0,D$2=0,$A3=D$2),0,(정산!$E$7=D$2)*(정산!$C$17="O")*정산!$G$7+(정산!$E$8=D$2)*(정산!$D$17="O")*정산!$G$8+(정산!$E$9=D$2)*(정산!$E$17="O")*정산!$G$9+(정산!$E$10=D$2)*(정산!$F$17="O")*정산!$G$10+(정산!$E$11=D$2)*(정산!$G$17="O")*정산!$G$11+(정산!$E$12=D$2)*(정산!$H$17="O")*정산!$G$12) -> 0 | E3: =IF(OR($A3=0,E$2=0,$A3=E$2),0,(정산!$E$7=E$2)*(정산!$C$17="O")*정산!$G$7+(정산!$E$8=E$2)*(정산!$D$17="O")*정산!$G$8+(정산!$E$9=E$2)*(정산!$E$17="O")*정산!$G$9+(정산!$E$10=E$2)*(정산!$F$17="O")*정산!$G$10+(정산!$E$11=E$2)*(정산!$G$17="O")*정산!$G$11+(정산!$E$12=E$2)*(정산!$H$17="O")*정산!$G$12) -> 0 | F3: =IF(OR($A3=0,F$2=0,$A3=F$2),0,(정산!$E$7=F$2)*(정산!$C$17="O")*정산!$G$7+(정산!$E$8=F$2)*(정산!$D$17="O")*정산!$G$8+(정산!$E$9=F$2)*(정산!$E$17="O")*정산!$G$9+(정산!$E$10=F$2)*(정산!$F$17="O")*정산!$G$10+(정산!$E$11=F$2)*(정산!$G$17="O")*정산!$G$11+(정산!$E$12=F$2)*(정산!$H$17="O")*정산!$G$12) -> 0 | G3: =IF(OR($A3=0,G$2=0,$A3=G$2),0,(정산!$E$7=G$2)*(정산!$C$17="O")*정산!$G$7+(정산!$E$8=G$2)*(정산!$D$17="O")*정산!$G$8+(정산!$E$9=G$2)*(정산!$E$17="O")*정산!$G$9+(정산!$E$10=G$2)*(정산!$F$17="O")*정산!$G$10+(정산!$E$11=G$2)*(정산!$G$17="O")*정산!$G$11+(정산!$E$12=G$2)*(정산!$H$17="O")*정산!$G$12) -> 0 | H3: =IF(OR($A3=0,H$2=0,$A3=H$2),0,(정산!$E$7=H$2)*(정산!$C$17="O")*정산!$G$7+(정산!$E$8=H$2)*(정산!$D$17="O")*정산!$G$8+(정산!$E$9=H$2)*(정산!$E$17="O")*정산!$G$9+(정산!$E$10=H$2)*(정산!$F$17="O")*정산!$G$10+(정산!$E$11=H$2)*(정산!$G$17="O")*정산!$G$11+(정산!$E$12=H$2)*(정산!$H$17="O")*정산!$G$12) -> 0 | I3: =IF(OR($A3=0,I$2=0,$A3=I$2),0,(정산!$E$7=I$2)*(정산!$C$17="O")*정산!$G$7+(정산!$E$8=I$2)*(정산!$D$17="O")*정산!$G$8+(정산!$E$9=I$2)*(정산!$E$17="O")*정산!$G$9+(정산!$E$10=I$2)*(정산!$F$17="O")*정산!$G$10+(정산!$E$11=I$2)*(정산!$G$17="O")*정산!$G$11+(정산!$E$12=I$2)*(정산!$H$17="O")*정산!$G$12) -> 0 | ... M3: =IF(OR($A3=0,M$2=0,$A3=M$2),0,(정산!$E$7=M$2)*(정산!$C$17="O")*정산!$G$7+(정산!$E$8=M$2)*(정산!$D$17="O")*정산!$G$8+(정산!$E$9=M$2)*(정산!$E$17="O")*정산!$G$9+(정산!$E$10=M$2)*(정산!$F$17="O")*정산!$G$10+(정산!$E$11=M$2)*(정산!$G$17="O")*정산!$G$11+(정산!$E$12=M$2)*(정산!$H$17="O")*정산!$G$12) -> 0
A4: =정산!B18 -> 지영 | B4: =IF(OR($A4=0,B$2=0,$A4=B$2),0,(정산!$E$7=B$2)*(정산!$C$18="O")*정산!$G$7+(정산!$E$8=B$2)*(정산!$D$18="O")*정산!$G$8+(정산!$E$9=B$2)*(정산!$E$18="O")*정산!$G$9+(정산!$E$10=B$2)*(정산!$F$18="O")*정산!$G$10+(정산!$E$11=B$2)*(정산!$G$18="O")*정산!$G$11+(정산!$E$12=B$2)*(정산!$H$18="O")*정산!$G$12) -> 40000 | C4: =IF(OR($A4=0,C$2=0,$A4=C$2),0,(정산!$E$7=C$2)*(정산!$C$18="O")*정산!$G$7+(정산!$E$8=C$2)*(정산!$D$18="O")*정산!$G$8+(정산!$E$9=C$2)*(정산!$E$18="O")*정산!$G$9+(정산!$E$10=C$2)*(정산!$F$18="O")*정산!$G$10+(정산!$E$11=C$2)*(정산!$G$18="O")*정산!$G$11+(정산!$E$12=C$2)*(정산!$H$18="O")*정산!$G$12) -> 0 | D4: =IF(OR($A4=0,D$2=0,$A4=D$2),0,(정산!$E$7=D$2)*(정산!$C$18="O")*정산!$G$7+(정산!$E$8=D$2)*(정산!$D$18="O")*정산!$G$8+(정산!$E$9=D$2)*(정산!$E$18="O")*정산!$G$9+(정산!$E$10=D$2)*(정산!$F$18="O")*정산!$G$10+(정산!$E$11=D$2)*(정산!$G$18="O")*정산!$G$11+(정산!$E$12=D$2)*(정산!$H$18="O")*정산!$G$12) -> 0 | E4: =IF(OR($A4=0,E$2=0,$A4=E$2),0,(정산!$E$7=E$2)*(정산!$C$18="O")*정산!$G$7+(정산!$E$8=E$2)*(정산!$D$18="O")*정산!$G$8+(정산!$E$9=E$2)*(정산!$E$18="O")*정산!$G$9+(정산!$E$10=E$2)*(정산!$F$18="O")*정산!$G$10+(정산!$E$11=E$2)*(정산!$G$18="O")*정산!$G$11+(정산!$E$12=E$2)*(정산!$H$18="O")*정산!$G$12) -> 0 | F4: =IF(OR($A4=0,F$2=0,$A4=F$2),0,(정산!$E$7=F$2)*(정산!$C$18="O")*정산!$G$7+(정산!$E$8=F$2)*(정산!$D$18="O")*정산!$G$8+(정산!$E$9=F$2)*(정산!$E$18="O")*정산!$G$9+(정산!$E$10=F$2)*(정산!$F$18="O")*정산!$G$10+(정산!$E$11=F$2)*(정산!$G$18="O")*정산!$G$11+(정산!$E$12=F$2)*(정산!$H$18="O")*정산!$G$12) -> 0 | G4: =IF(OR($A4=0,G$2=0,$A4=G$2),0,(정산!$E$7=G$2)*(정산!$C$18="O")*정산!$G$7+(정산!$E$8=G$2)*(정산!$D$18="O")*정산!$G$8+(정산!$E$9=G$2)*(정산!$E$18="O")*정산!$G$9+(정산!$E$10=G$2)*(정산!$F$18="O")*정산!$G$10+(정산!$E$11=G$2)*(정산!$G$18="O")*정산!$G$11+(정산!$E$12=G$2)*(정산!$H$18="O")*정산!$G$12) -> 0 | H4: =IF(OR($A4=0,H$2=0,$A4=H$2),0,(정산!$E$7=H$2)*(정산!$C$18="O")*정산!$G$7+(정산!$E$8=H$2)*(정산!$D$18="O")*정산!$G$8+(정산!$E$9=H$2)*(정산!$E$18="O")*정산!$G$9+(정산!$E$10=H$2)*(정산!$F$18="O")*정산!$G$10+(정산!$E$11=H$2)*(정산!$G$18="O")*정산!$G$11+(정산!$E$12=H$2)*(정산!$H$18="O")*정산!$G$12) -> 0 | I4: =IF(OR($A4=0,I$2=0,$A4=I$2),0,(정산!$E$7=I$2)*(정산!$C$18="O")*정산!$G$7+(정산!$E$8=I$2)*(정산!$D$18="O")*정산!$G$8+(정산!$E$9=I$2)*(정산!$E$18="O")*정산!$G$9+(정산!$E$10=I$2)*(정산!$F$18="O")*정산!$G$10+(정산!$E$11=I$2)*(정산!$G$18="O")*정산!$G$11+(정산!$E$12=I$2)*(정산!$H$18="O")*정산!$G$12) -> 0 | ... M4: =IF(OR($A4=0,M$2=0,$A4=M$2),0,(정산!$E$7=M$2)*(정산!$C$18="O")*정산!$G$7+(정산!$E$8=M$2)*(정산!$D$18="O")*정산!$G$8+(정산!$E$9=M$2)*(정산!$E$18="O")*정산!$G$9+(정산!$E$10=M$2)*(정산!$F$18="O")*정산!$G$10+(정산!$E$11=M$2)*(정산!$G$18="O")*정산!$G$11+(정산!$E$12=M$2)*(정산!$H$18="O")*정산!$G$12) -> 0
A5: =정산!B19 -> 철수 | B5: =IF(OR($A5=0,B$2=0,$A5=B$2),0,(정산!$E$7=B$2)*(정산!$C$19="O")*정산!$G$7+(정산!$E$8=B$2)*(정산!$D$19="O")*정산!$G$8+(정산!$E$9=B$2)*(정산!$E$19="O")*정산!$G$9+(정산!$E$10=B$2)*(정산!$F$19="O")*정산!$G$10+(정산!$E$11=B$2)*(정산!$G$19="O")*정산!$G$11+(정산!$E$12=B$2)*(정산!$H$19="O")*정산!$G$12) -> 30000 | C5: =IF(OR($A5=0,C$2=0,$A5=C$2),0,(정산!$E$7=C$2)*(정산!$C$19="O")*정산!$G$7+(정산!$E$8=C$2)*(정산!$D$19="O")*정산!$G$8+(정산!$E$9=C$2)*(정산!$E$19="O")*정산!$G$9+(정산!$E$10=C$2)*(정산!$F$19="O")*정산!$G$10+(정산!$E$11=C$2)*(정산!$G$19="O")*정산!$G$11+(정산!$E$12=C$2)*(정산!$H$19="O")*정산!$G$12) -> 21250 | D5: =IF(OR($A5=0,D$2=0,$A5=D$2),0,(정산!$E$7=D$2)*(정산!$C$19="O")*정산!$G$7+(정산!$E$8=D$2)*(정산!$D$19="O")*정산!$G$8+(정산!$E$9=D$2)*(정산!$E$19="O")*정산!$G$9+(정산!$E$10=D$2)*(정산!$F$19="O")*정산!$G$10+(정산!$E$11=D$2)*(정산!$G$19="O")*정산!$G$11+(정산!$E$12=D$2)*(정산!$H$19="O")*정산!$G$12) -> 0 | E5: =IF(OR($A5=0,E$2=0,$A5=E$2),0,(정산!$E$7=E$2)*(정산!$C$19="O")*정산!$G$7+(정산!$E$8=E$2)*(정산!$D$19="O")*정산!$G$8+(정산!$E$9=E$2)*(정산!$E$19="O")*정산!$G$9+(정산!$E$10=E$2)*(정산!$F$19="O")*정산!$G$10+(정산!$E$11=E$2)*(정산!$G$19="O")*정산!$G$11+(정산!$E$12=E$2)*(정산!$H$19="O")*정산!$G$12) -> 0 | F5: =IF(OR($A5=0,F$2=0,$A5=F$2),0,(정산!$E$7=F$2)*(정산!$C$19="O")*정산!$G$7+(정산!$E$8=F$2)*(정산!$D$19="O")*정산!$G$8+(정산!$E$9=F$2)*(정산!$E$19="O")*정산!$G$9+(정산!$E$10=F$2)*(정산!$F$19="O")*정산!$G$10+(정산!$E$11=F$2)*(정산!$G$19="O")*정산!$G$11+(정산!$E$12=F$2)*(정산!$H$19="O")*정산!$G$12) -> 0 | G5: =IF(OR($A5=0,G$2=0,$A5=G$2),0,(정산!$E$7=G$2)*(정산!$C$19="O")*정산!$G$7+(정산!$E$8=G$2)*(정산!$D$19="O")*정산!$G$8+(정산!$E$9=G$2)*(정산!$E$19="O")*정산!$G$9+(정산!$E$10=G$2)*(정산!$F$19="O")*정산!$G$10+(정산!$E$11=G$2)*(정산!$G$19="O")*정산!$G$11+(정산!$E$12=G$2)*(정산!$H$19="O")*정산!$G$12) -> 0 | H5: =IF(OR($A5=0,H$2=0,$A5=H$2),0,(정산!$E$7=H$2)*(정산!$C$19="O")*정산!$G$7+(정산!$E$8=H$2)*(정산!$D$19="O")*정산!$G$8+(정산!$E$9=H$2)*(정산!$E$19="O")*정산!$G$9+(정산!$E$10=H$2)*(정산!$F$19="O")*정산!$G$10+(정산!$E$11=H$2)*(정산!$G$19="O")*정산!$G$11+(정산!$E$12=H$2)*(정산!$H$19="O")*정산!$G$12) -> 0 | I5: =IF(OR($A5=0,I$2=0,$A5=I$2),0,(정산!$E$7=I$2)*(정산!$C$19="O")*정산!$G$7+(정산!$E$8=I$2)*(정산!$D$19="O")*정산!$G$8+(정산!$E$9=I$2)*(정산!$E$19="O")*정산!$G$9+(정산!$E$10=I$2)*(정산!$F$19="O")*정산!$G$10+(정산!$E$11=I$2)*(정산!$G$19="O")*정산!$G$11+(정산!$E$12=I$2)*(정산!$H$19="O")*정산!$G$12) -> 0 | ... M5: =IF(OR($A5=0,M$2=0,$A5=M$2),0,(정산!$E$7=M$2)*(정산!$C$19="O")*정산!$G$7+(정산!$E$8=M$2)*(정산!$D$19="O")*정산!$G$8+(정산!$E$9=M$2)*(정산!$E$19="O")*정산!$G$9+(정산!$E$10=M$2)*(정산!$F$19="O")*정산!$G$10+(정산!$E$11=M$2)*(정산!$G$19="O")*정산!$G$11+(정산!$E$12=M$2)*(정산!$H$19="O")*정산!$G$12) -> 0
A6: =정산!B20 -> 영희 | B6: =IF(OR($A6=0,B$2=0,$A6=B$2),0,(정산!$E$7=B$2)*(정산!$C$20="O")*정산!$G$7+(정산!$E$8=B$2)*(정산!$D$20="O")*정산!$G$8+(정산!$E$9=B$2)*(정산!$E$20="O")*정산!$G$9+(정산!$E$10=B$2)*(정산!$F$20="O")*정산!$G$10+(정산!$E$11=B$2)*(정산!$G$20="O")*정산!$G$11+(정산!$E$12=B$2)*(정산!$H$20="O")*정산!$G$12) -> 40000 | C6: =IF(OR($A6=0,C$2=0,$A6=C$2),0,(정산!$E$7=C$2)*(정산!$C$20="O")*정산!$G$7+(정산!$E$8=C$2)*(정산!$D$20="O")*정산!$G$8+(정산!$E$9=C$2)*(정산!$E$20="O")*정산!$G$9+(정산!$E$10=C$2)*(정산!$F$20="O")*정산!$G$10+(정산!$E$11=C$2)*(정산!$G$20="O")*정산!$G$11+(정산!$E$12=C$2)*(정산!$H$20="O")*정산!$G$12) -> 0 | D6: =IF(OR($A6=0,D$2=0,$A6=D$2),0,(정산!$E$7=D$2)*(정산!$C$20="O")*정산!$G$7+(정산!$E$8=D$2)*(정산!$D$20="O")*정산!$G$8+(정산!$E$9=D$2)*(정산!$E$20="O")*정산!$G$9+(정산!$E$10=D$2)*(정산!$F$20="O")*정산!$G$10+(정산!$E$11=D$2)*(정산!$G$20="O")*정산!$G$11+(정산!$E$12=D$2)*(정산!$H$20="O")*정산!$G$12) -> 0 | E6: =IF(OR($A6=0,E$2=0,$A6=E$2),0,(정산!$E$7=E$2)*(정산!$C$20="O")*정산!$G$7+(정산!$E$8=E$2)*(정산!$D$20="O")*정산!$G$8+(정산!$E$9=E$2)*(정산!$E$20="O")*정산!$G$9+(정산!$E$10=E$2)*(정산!$F$20="O")*정산!$G$10+(정산!$E$11=E$2)*(정산!$G$20="O")*정산!$G$11+(정산!$E$12=E$2)*(정산!$H$20="O")*정산!$G$12) -> 0 | F6: =IF(OR($A6=0,F$2=0,$A6=F$2),0,(정산!$E$7=F$2)*(정산!$C$20="O")*정산!$G$7+(정산!$E$8=F$2)*(정산!$D$20="O")*정산!$G$8+(정산!$E$9=F$2)*(정산!$E$20="O")*정산!$G$9+(정산!$E$10=F$2)*(정산!$F$20="O")*정산!$G$10+(정산!$E$11=F$2)*(정산!$G$20="O")*정산!$G$11+(정산!$E$12=F$2)*(정산!$H$20="O")*정산!$G$12) -> 0 | G6: =IF(OR($A6=0,G$2=0,$A6=G$2),0,(정산!$E$7=G$2)*(정산!$C$20="O")*정산!$G$7+(정산!$E$8=G$2)*(정산!$D$20="O")*정산!$G$8+(정산!$E$9=G$2)*(정산!$E$20="O")*정산!$G$9+(정산!$E$10=G$2)*(정산!$F$20="O")*정산!$G$10+(정산!$E$11=G$2)*(정산!$G$20="O")*정산!$G$11+(정산!$E$12=G$2)*(정산!$H$20="O")*정산!$G$12) -> 0 | H6: =IF(OR($A6=0,H$2=0,$A6=H$2),0,(정산!$E$7=H$2)*(정산!$C$20="O")*정산!$G$7+(정산!$E$8=H$2)*(정산!$D$20="O")*정산!$G$8+(정산!$E$9=H$2)*(정산!$E$20="O")*정산!$G$9+(정산!$E$10=H$2)*(정산!$F$20="O")*정산!$G$10+(정산!$E$11=H$2)*(정산!$G$20="O")*정산!$G$11+(정산!$E$12=H$2)*(정산!$H$20="O")*정산!$G$12) -> 0 | I6: =IF(OR($A6=0,I$2=0,$A6=I$2),0,(정산!$E$7=I$2)*(정산!$C$20="O")*정산!$G$7+(정산!$E$8=I$2)*(정산!$D$20="O")*정산!$G$8+(정산!$E$9=I$2)*(정산!$E$20="O")*정산!$G$9+(정산!$E$10=I$2)*(정산!$F$20="O")*정산!$G$10+(정산!$E$11=I$2)*(정산!$G$20="O")*정산!$G$11+(정산!$E$12=I$2)*(정산!$H$20="O")*정산!$G$12) -> 0 | ... M6: =IF(OR($A6=0,M$2=0,$A6=M$2),0,(정산!$E$7=M$2)*(정산!$C$20="O")*정산!$G$7+(정산!$E$8=M$2)*(정산!$D$20="O")*정산!$G$8+(정산!$E$9=M$2)*(정산!$E$20="O")*정산!$G$9+(정산!$E$10=M$2)*(정산!$F$20="O")*정산!$G$10+(정산!$E$11=M$2)*(정산!$G$20="O")*정산!$G$11+(정산!$E$12=M$2)*(정산!$H$20="O")*정산!$G$12) -> 0
A7: =정산!B21 -> 준호 | B7: =IF(OR($A7=0,B$2=0,$A7=B$2),0,(정산!$E$7=B$2)*(정산!$C$21="O")*정산!$G$7+(정산!$E$8=B$2)*(정산!$D$21="O")*정산!$G$8+(정산!$E$9=B$2)*(정산!$E$21="O")*정산!$G$9+(정산!$E$10=B$2)*(정산!$F$21="O")*정산!$G$10+(정산!$E$11=B$2)*(정산!$G$21="O")*정산!$G$11+(정산!$E$12=B$2)*(정산!$H$21="O")*정산!$G$12) -> 10000 | C7: =IF(OR($A7=0,C$2=0,$A7=C$2),0,(정산!$E$7=C$2)*(정산!$C$21="O")*정산!$G$7+(정산!$E$8=C$2)*(정산!$D$21="O")*정산!$G$8+(정산!$E$9=C$2)*(정산!$E$21="O")*정산!$G$9+(정산!$E$10=C$2)*(정산!$F$21="O")*정산!$G$10+(정산!$E$11=C$2)*(정산!$G$21="O")*정산!$G$11+(정산!$E$12=C$2)*(정산!$H$21="O")*정산!$G$12) -> 21250 | D7: =IF(OR($A7=0,D$2=0,$A7=D$2),0,(정산!$E$7=D$2)*(정산!$C$21="O")*정산!$G$7+(정산!$E$8=D$2)*(정산!$D$21="O")*정산!$G$8+(정산!$E$9=D$2)*(정산!$E$21="O")*정산!$G$9+(정산!$E$10=D$2)*(정산!$F$21="O")*정산!$G$10+(정산!$E$11=D$2)*(정산!$G$21="O")*정산!$G$11+(정산!$E$12=D$2)*(정산!$H$21="O")*정산!$G$12) -> 0 | E7: =IF(OR($A7=0,E$2=0,$A7=E$2),0,(정산!$E$7=E$2)*(정산!$C$21="O")*정산!$G$7+(정산!$E$8=E$2)*(정산!$D$21="O")*정산!$G$8+(정산!$E$9=E$2)*(정산!$E$21="O")*정산!$G$9+(정산!$E$10=E$2)*(정산!$F$21="O")*정산!$G$10+(정산!$E$11=E$2)*(정산!$G$21="O")*정산!$G$11+(정산!$E$12=E$2)*(정산!$H$21="O")*정산!$G$12) -> 0 | F7: =IF(OR($A7=0,F$2=0,$A7=F$2),0,(정산!$E$7=F$2)*(정산!$C$21="O")*정산!$G$7+(정산!$E$8=F$2)*(정산!$D$21="O")*정산!$G$8+(정산!$E$9=F$2)*(정산!$E$21="O")*정산!$G$9+(정산!$E$10=F$2)*(정산!$F$21="O")*정산!$G$10+(정산!$E$11=F$2)*(정산!$G$21="O")*정산!$G$11+(정산!$E$12=F$2)*(정산!$H$21="O")*정산!$G$12) -> 0 | G7: =IF(OR($A7=0,G$2=0,$A7=G$2),0,(정산!$E$7=G$2)*(정산!$C$21="O")*정산!$G$7+(정산!$E$8=G$2)*(정산!$D$21="O")*정산!$G$8+(정산!$E$9=G$2)*(정산!$E$21="O")*정산!$G$9+(정산!$E$10=G$2)*(정산!$F$21="O")*정산!$G$10+(정산!$E$11=G$2)*(정산!$G$21="O")*정산!$G$11+(정산!$E$12=G$2)*(정산!$H$21="O")*정산!$G$12) -> 0 | H7: =IF(OR($A7=0,H$2=0,$A7=H$2),0,(정산!$E$7=H$2)*(정산!$C$21="O")*정산!$G$7+(정산!$E$8=H$2)*(정산!$D$21="O")*정산!$G$8+(정산!$E$9=H$2)*(정산!$E$21="O")*정산!$G$9+(정산!$E$10=H$2)*(정산!$F$21="O")*정산!$G$10+(정산!$E$11=H$2)*(정산!$G$21="O")*정산!$G$11+(정산!$E$12=H$2)*(정산!$H$21="O")*정산!$G$12) -> 0 | I7: =IF(OR($A7=0,I$2=0,$A7=I$2),0,(정산!$E$7=I$2)*(정산!$C$21="O")*정산!$G$7+(정산!$E$8=I$2)*(정산!$D$21="O")*정산!$G$8+(정산!$E$9=I$2)*(정산!$E$21="O")*정산!$G$9+(정산!$E$10=I$2)*(정산!$F$21="O")*정산!$G$10+(정산!$E$11=I$2)*(정산!$G$21="O")*정산!$G$11+(정산!$E$12=I$2)*(정산!$H$21="O")*정산!$G$12) -> 0 | ... M7: =IF(OR($A7=0,M$2=0,$A7=M$2),0,(정산!$E$7=M$2)*(정산!$C$21="O")*정산!$G$7+(정산!$E$8=M$2)*(정산!$D$21="O")*정산!$G$8+(정산!$E$9=M$2)*(정산!$E$21="O")*정산!$G$9+(정산!$E$10=M$2)*(정산!$F$21="O")*정산!$G$10+(정산!$E$11=M$2)*(정산!$G$21="O")*정산!$G$11+(정산!$E$12=M$2)*(정산!$H$21="O")*정산!$G$12) -> 0
A8: =정산!B22 -> 0 | B8: =IF(OR($A8=0,B$2=0,$A8=B$2),0,(정산!$E$7=B$2)*(정산!$C$22="O")*정산!$G$7+(정산!$E$8=B$2)*(정산!$D$22="O")*정산!$G$8+(정산!$E$9=B$2)*(정산!$E$22="O")*정산!$G$9+(정산!$E$10=B$2)*(정산!$F$22="O")*정산!$G$10+(정산!$E$11=B$2)*(정산!$G$22="O")*정산!$G$11+(정산!$E$12=B$2)*(정산!$H$22="O")*정산!$G$12) -> 0 | C8: =IF(OR($A8=0,C$2=0,$A8=C$2),0,(정산!$E$7=C$2)*(정산!$C$22="O")*정산!$G$7+(정산!$E$8=C$2)*(정산!$D$22="O")*정산!$G$8+(정산!$E$9=C$2)*(정산!$E$22="O")*정산!$G$9+(정산!$E$10=C$2)*(정산!$F$22="O")*정산!$G$10+(정산!$E$11=C$2)*(정산!$G$22="O")*정산!$G$11+(정산!$E$12=C$2)*(정산!$H$22="O")*정산!$G$12) -> 0 | D8: =IF(OR($A8=0,D$2=0,$A8=D$2),0,(정산!$E$7=D$2)*(정산!$C$22="O")*정산!$G$7+(정산!$E$8=D$2)*(정산!$D$22="O")*정산!$G$8+(정산!$E$9=D$2)*(정산!$E$22="O")*정산!$G$9+(정산!$E$10=D$2)*(정산!$F$22="O")*정산!$G$10+(정산!$E$11=D$2)*(정산!$G$22="O")*정산!$G$11+(정산!$E$12=D$2)*(정산!$H$22="O")*정산!$G$12) -> 0 | E8: =IF(OR($A8=0,E$2=0,$A8=E$2),0,(정산!$E$7=E$2)*(정산!$C$22="O")*정산!$G$7+(정산!$E$8=E$2)*(정산!$D$22="O")*정산!$G$8+(정산!$E$9=E$2)*(정산!$E$22="O")*정산!$G$9+(정산!$E$10=E$2)*(정산!$F$22="O")*정산!$G$10+(정산!$E$11=E$2)*(정산!$G$22="O")*정산!$G$11+(정산!$E$12=E$2)*(정산!$H$22="O")*정산!$G$12) -> 0 | F8: =IF(OR($A8=0,F$2=0,$A8=F$2),0,(정산!$E$7=F$2)*(정산!$C$22="O")*정산!$G$7+(정산!$E$8=F$2)*(정산!$D$22="O")*정산!$G$8+(정산!$E$9=F$2)*(정산!$E$22="O")*정산!$G$9+(정산!$E$10=F$2)*(정산!$F$22="O")*정산!$G$10+(정산!$E$11=F$2)*(정산!$G$22="O")*정산!$G$11+(정산!$E$12=F$2)*(정산!$H$22="O")*정산!$G$12) -> 0 | G8: =IF(OR($A8=0,G$2=0,$A8=G$2),0,(정산!$E$7=G$2)*(정산!$C$22="O")*정산!$G$7+(정산!$E$8=G$2)*(정산!$D$22="O")*정산!$G$8+(정산!$E$9=G$2)*(정산!$E$22="O")*정산!$G$9+(정산!$E$10=G$2)*(정산!$F$22="O")*정산!$G$10+(정산!$E$11=G$2)*(정산!$G$22="O")*정산!$G$11+(정산!$E$12=G$2)*(정산!$H$22="O")*정산!$G$12) -> 0 | H8: =IF(OR($A8=0,H$2=0,$A8=H$2),0,(정산!$E$7=H$2)*(정산!$C$22="O")*정산!$G$7+(정산!$E$8=H$2)*(정산!$D$22="O")*정산!$G$8+(정산!$E$9=H$2)*(정산!$E$22="O")*정산!$G$9+(정산!$E$10=H$2)*(정산!$F$22="O")*정산!$G$10+(정산!$E$11=H$2)*(정산!$G$22="O")*정산!$G$11+(정산!$E$12=H$2)*(정산!$H$22="O")*정산!$G$12) -> 0 | I8: =IF(OR($A8=0,I$2=0,$A8=I$2),0,(정산!$E$7=I$2)*(정산!$C$22="O")*정산!$G$7+(정산!$E$8=I$2)*(정산!$D$22="O")*정산!$G$8+(정산!$E$9=I$2)*(정산!$E$22="O")*정산!$G$9+(정산!$E$10=I$2)*(정산!$F$22="O")*정산!$G$10+(정산!$E$11=I$2)*(정산!$G$22="O")*정산!$G$11+(정산!$E$12=I$2)*(정산!$H$22="O")*정산!$G$12) -> 0 | ... M8: =IF(OR($A8=0,M$2=0,$A8=M$2),0,(정산!$E$7=M$2)*(정산!$C$22="O")*정산!$G$7+(정산!$E$8=M$2)*(정산!$D$22="O")*정산!$G$8+(정산!$E$9=M$2)*(정산!$E$22="O")*정산!$G$9+(정산!$E$10=M$2)*(정산!$F$22="O")*정산!$G$10+(정산!$E$11=M$2)*(정산!$G$22="O")*정산!$G$11+(정산!$E$12=M$2)*(정산!$H$22="O")*정산!$G$12) -> 0
A9: =정산!B23 -> 0 | B9: =IF(OR($A9=0,B$2=0,$A9=B$2),0,(정산!$E$7=B$2)*(정산!$C$23="O")*정산!$G$7+(정산!$E$8=B$2)*(정산!$D$23="O")*정산!$G$8+(정산!$E$9=B$2)*(정산!$E$23="O")*정산!$G$9+(정산!$E$10=B$2)*(정산!$F$23="O")*정산!$G$10+(정산!$E$11=B$2)*(정산!$G$23="O")*정산!$G$11+(정산!$E$12=B$2)*(정산!$H$23="O")*정산!$G$12) -> 0 | C9: =IF(OR($A9=0,C$2=0,$A9=C$2),0,(정산!$E$7=C$2)*(정산!$C$23="O")*정산!$G$7+(정산!$E$8=C$2)*(정산!$D$23="O")*정산!$G$8+(정산!$E$9=C$2)*(정산!$E$23="O")*정산!$G$9+(정산!$E$10=C$2)*(정산!$F$23="O")*정산!$G$10+(정산!$E$11=C$2)*(정산!$G$23="O")*정산!$G$11+(정산!$E$12=C$2)*(정산!$H$23="O")*정산!$G$12) -> 0 | D9: =IF(OR($A9=0,D$2=0,$A9=D$2),0,(정산!$E$7=D$2)*(정산!$C$23="O")*정산!$G$7+(정산!$E$8=D$2)*(정산!$D$23="O")*정산!$G$8+(정산!$E$9=D$2)*(정산!$E$23="O")*정산!$G$9+(정산!$E$10=D$2)*(정산!$F$23="O")*정산!$G$10+(정산!$E$11=D$2)*(정산!$G$23="O")*정산!$G$11+(정산!$E$12=D$2)*(정산!$H$23="O")*정산!$G$12) -> 0 | E9: =IF(OR($A9=0,E$2=0,$A9=E$2),0,(정산!$E$7=E$2)*(정산!$C$23="O")*정산!$G$7+(정산!$E$8=E$2)*(정산!$D$23="O")*정산!$G$8+(정산!$E$9=E$2)*(정산!$E$23="O")*정산!$G$9+(정산!$E$10=E$2)*(정산!$F$23="O")*정산!$G$10+(정산!$E$11=E$2)*(정산!$G$23="O")*정산!$G$11+(정산!$E$12=E$2)*(정산!$H$23="O")*정산!$G$12) -> 0 | F9: =IF(OR($A9=0,F$2=0,$A9=F$2),0,(정산!$E$7=F$2)*(정산!$C$23="O")*정산!$G$7+(정산!$E$8=F$2)*(정산!$D$23="O")*정산!$G$8+(정산!$E$9=F$2)*(정산!$E$23="O")*정산!$G$9+(정산!$E$10=F$2)*(정산!$F$23="O")*정산!$G$10+(정산!$E$11=F$2)*(정산!$G$23="O")*정산!$G$11+(정산!$E$12=F$2)*(정산!$H$23="O")*정산!$G$12) -> 0 | G9: =IF(OR($A9=0,G$2=0,$A9=G$2),0,(정산!$E$7=G$2)*(정산!$C$23="O")*정산!$G$7+(정산!$E$8=G$2)*(정산!$D$23="O")*정산!$G$8+(정산!$E$9=G$2)*(정산!$E$23="O")*정산!$G$9+(정산!$E$10=G$2)*(정산!$F$23="O")*정산!$G$10+(정산!$E$11=G$2)*(정산!$G$23="O")*정산!$G$11+(정산!$E$12=G$2)*(정산!$H$23="O")*정산!$G$12) -> 0 | H9: =IF(OR($A9=0,H$2=0,$A9=H$2),0,(정산!$E$7=H$2)*(정산!$C$23="O")*정산!$G$7+(정산!$E$8=H$2)*(정산!$D$23="O")*정산!$G$8+(정산!$E$9=H$2)*(정산!$E$23="O")*정산!$G$9+(정산!$E$10=H$2)*(정산!$F$23="O")*정산!$G$10+(정산!$E$11=H$2)*(정산!$G$23="O")*정산!$G$11+(정산!$E$12=H$2)*(정산!$H$23="O")*정산!$G$12) -> 0 | I9: =IF(OR($A9=0,I$2=0,$A9=I$2),0,(정산!$E$7=I$2)*(정산!$C$23="O")*정산!$G$7+(정산!$E$8=I$2)*(정산!$D$23="O")*정산!$G$8+(정산!$E$9=I$2)*(정산!$E$23="O")*정산!$G$9+(정산!$E$10=I$2)*(정산!$F$23="O")*정산!$G$10+(정산!$E$11=I$2)*(정산!$G$23="O")*정산!$G$11+(정산!$E$12=I$2)*(정산!$H$23="O")*정산!$G$12) -> 0 | ... M9: =IF(OR($A9=0,M$2=0,$A9=M$2),0,(정산!$E$7=M$2)*(정산!$C$23="O")*정산!$G$7+(정산!$E$8=M$2)*(정산!$D$23="O")*정산!$G$8+(정산!$E$9=M$2)*(정산!$E$23="O")*정산!$G$9+(정산!$E$10=M$2)*(정산!$F$23="O")*정산!$G$10+(정산!$E$11=M$2)*(정산!$G$23="O")*정산!$G$11+(정산!$E$12=M$2)*(정산!$H$23="O")*정산!$G$12) -> 0
A10: =정산!B24 -> 0 | B10: =IF(OR($A10=0,B$2=0,$A10=B$2),0,(정산!$E$7=B$2)*(정산!$C$24="O")*정산!$G$7+(정산!$E$8=B$2)*(정산!$D$24="O")*정산!$G$8+(정산!$E$9=B$2)*(정산!$E$24="O")*정산!$G$9+(정산!$E$10=B$2)*(정산!$F$24="O")*정산!$G$10+(정산!$E$11=B$2)*(정산!$G$24="O")*정산!$G$11+(정산!$E$12=B$2)*(정산!$H$24="O")*정산!$G$12) -> 0 | C10: =IF(OR($A10=0,C$2=0,$A10=C$2),0,(정산!$E$7=C$2)*(정산!$C$24="O")*정산!$G$7+(정산!$E$8=C$2)*(정산!$D$24="O")*정산!$G$8+(정산!$E$9=C$2)*(정산!$E$24="O")*정산!$G$9+(정산!$E$10=C$2)*(정산!$F$24="O")*정산!$G$10+(정산!$E$11=C$2)*(정산!$G$24="O")*정산!$G$11+(정산!$E$12=C$2)*(정산!$H$24="O")*정산!$G$12) -> 0 | D10: =IF(OR($A10=0,D$2=0,$A10=D$2),0,(정산!$E$7=D$2)*(정산!$C$24="O")*정산!$G$7+(정산!$E$8=D$2)*(정산!$D$24="O")*정산!$G$8+(정산!$E$9=D$2)*(정산!$E$24="O")*정산!$G$9+(정산!$E$10=D$2)*(정산!$F$24="O")*정산!$G$10+(정산!$E$11=D$2)*(정산!$G$24="O")*정산!$G$11+(정산!$E$12=D$2)*(정산!$H$24="O")*정산!$G$12) -> 0 | E10: =IF(OR($A10=0,E$2=0,$A10=E$2),0,(정산!$E$7=E$2)*(정산!$C$24="O")*정산!$G$7+(정산!$E$8=E$2)*(정산!$D$24="O")*정산!$G$8+(정산!$E$9=E$2)*(정산!$E$24="O")*정산!$G$9+(정산!$E$10=E$2)*(정산!$F$24="O")*정산!$G$10+(정산!$E$11=E$2)*(정산!$G$24="O")*정산!$G$11+(정산!$E$12=E$2)*(정산!$H$24="O")*정산!$G$12) -> 0 | F10: =IF(OR($A10=0,F$2=0,$A10=F$2),0,(정산!$E$7=F$2)*(정산!$C$24="O")*정산!$G$7+(정산!$E$8=F$2)*(정산!$D$24="O")*정산!$G$8+(정산!$E$9=F$2)*(정산!$E$24="O")*정산!$G$9+(정산!$E$10=F$2)*(정산!$F$24="O")*정산!$G$10+(정산!$E$11=F$2)*(정산!$G$24="O")*정산!$G$11+(정산!$E$12=F$2)*(정산!$H$24="O")*정산!$G$12) -> 0 | G10: =IF(OR($A10=0,G$2=0,$A10=G$2),0,(정산!$E$7=G$2)*(정산!$C$24="O")*정산!$G$7+(정산!$E$8=G$2)*(정산!$D$24="O")*정산!$G$8+(정산!$E$9=G$2)*(정산!$E$24="O")*정산!$G$9+(정산!$E$10=G$2)*(정산!$F$24="O")*정산!$G$10+(정산!$E$11=G$2)*(정산!$G$24="O")*정산!$G$11+(정산!$E$12=G$2)*(정산!$H$24="O")*정산!$G$12) -> 0 | H10: =IF(OR($A10=0,H$2=0,$A10=H$2),0,(정산!$E$7=H$2)*(정산!$C$24="O")*정산!$G$7+(정산!$E$8=H$2)*(정산!$D$24="O")*정산!$G$8+(정산!$E$9=H$2)*(정산!$E$24="O")*정산!$G$9+(정산!$E$10=H$2)*(정산!$F$24="O")*정산!$G$10+(정산!$E$11=H$2)*(정산!$G$24="O")*정산!$G$11+(정산!$E$12=H$2)*(정산!$H$24="O")*정산!$G$12) -> 0 | I10: =IF(OR($A10=0,I$2=0,$A10=I$2),0,(정산!$E$7=I$2)*(정산!$C$24="O")*정산!$G$7+(정산!$E$8=I$2)*(정산!$D$24="O")*정산!$G$8+(정산!$E$9=I$2)*(정산!$E$24="O")*정산!$G$9+(정산!$E$10=I$2)*(정산!$F$24="O")*정산!$G$10+(정산!$E$11=I$2)*(정산!$G$24="O")*정산!$G$11+(정산!$E$12=I$2)*(정산!$H$24="O")*정산!$G$12) -> 0 | ... M10: =IF(OR($A10=0,M$2=0,$A10=M$2),0,(정산!$E$7=M$2)*(정산!$C$24="O")*정산!$G$7+(정산!$E$8=M$2)*(정산!$D$24="O")*정산!$G$8+(정산!$E$9=M$2)*(정산!$E$24="O")*정산!$G$9+(정산!$E$10=M$2)*(정산!$F$24="O")*정산!$G$10+(정산!$E$11=M$2)*(정산!$G$24="O")*정산!$G$11+(정산!$E$12=M$2)*(정산!$H$24="O")*정산!$G$12) -> 0
A11: =정산!B25 -> 0 | B11: =IF(OR($A11=0,B$2=0,$A11=B$2),0,(정산!$E$7=B$2)*(정산!$C$25="O")*정산!$G$7+(정산!$E$8=B$2)*(정산!$D$25="O")*정산!$G$8+(정산!$E$9=B$2)*(정산!$E$25="O")*정산!$G$9+(정산!$E$10=B$2)*(정산!$F$25="O")*정산!$G$10+(정산!$E$11=B$2)*(정산!$G$25="O")*정산!$G$11+(정산!$E$12=B$2)*(정산!$H$25="O")*정산!$G$12) -> 0 | C11: =IF(OR($A11=0,C$2=0,$A11=C$2),0,(정산!$E$7=C$2)*(정산!$C$25="O")*정산!$G$7+(정산!$E$8=C$2)*(정산!$D$25="O")*정산!$G$8+(정산!$E$9=C$2)*(정산!$E$25="O")*정산!$G$9+(정산!$E$10=C$2)*(정산!$F$25="O")*정산!$G$10+(정산!$E$11=C$2)*(정산!$G$25="O")*정산!$G$11+(정산!$E$12=C$2)*(정산!$H$25="O")*정산!$G$12) -> 0 | D11: =IF(OR($A11=0,D$2=0,$A11=D$2),0,(정산!$E$7=D$2)*(정산!$C$25="O")*정산!$G$7+(정산!$E$8=D$2)*(정산!$D$25="O")*정산!$G$8+(정산!$E$9=D$2)*(정산!$E$25="O")*정산!$G$9+(정산!$E$10=D$2)*(정산!$F$25="O")*정산!$G$10+(정산!$E$11=D$2)*(정산!$G$25="O")*정산!$G$11+(정산!$E$12=D$2)*(정산!$H$25="O")*정산!$G$12) -> 0 | E11: =IF(OR($A11=0,E$2=0,$A11=E$2),0,(정산!$E$7=E$2)*(정산!$C$25="O")*정산!$G$7+(정산!$E$8=E$2)*(정산!$D$25="O")*정산!$G$8+(정산!$E$9=E$2)*(정산!$E$25="O")*정산!$G$9+(정산!$E$10=E$2)*(정산!$F$25="O")*정산!$G$10+(정산!$E$11=E$2)*(정산!$G$25="O")*정산!$G$11+(정산!$E$12=E$2)*(정산!$H$25="O")*정산!$G$12) -> 0 | F11: =IF(OR($A11=0,F$2=0,$A11=F$2),0,(정산!$E$7=F$2)*(정산!$C$25="O")*정산!$G$7+(정산!$E$8=F$2)*(정산!$D$25="O")*정산!$G$8+(정산!$E$9=F$2)*(정산!$E$25="O")*정산!$G$9+(정산!$E$10=F$2)*(정산!$F$25="O")*정산!$G$10+(정산!$E$11=F$2)*(정산!$G$25="O")*정산!$G$11+(정산!$E$12=F$2)*(정산!$H$25="O")*정산!$G$12) -> 0 | G11: =IF(OR($A11=0,G$2=0,$A11=G$2),0,(정산!$E$7=G$2)*(정산!$C$25="O")*정산!$G$7+(정산!$E$8=G$2)*(정산!$D$25="O")*정산!$G$8+(정산!$E$9=G$2)*(정산!$E$25="O")*정산!$G$9+(정산!$E$10=G$2)*(정산!$F$25="O")*정산!$G$10+(정산!$E$11=G$2)*(정산!$G$25="O")*정산!$G$11+(정산!$E$12=G$2)*(정산!$H$25="O")*정산!$G$12) -> 0 | H11: =IF(OR($A11=0,H$2=0,$A11=H$2),0,(정산!$E$7=H$2)*(정산!$C$25="O")*정산!$G$7+(정산!$E$8=H$2)*(정산!$D$25="O")*정산!$G$8+(정산!$E$9=H$2)*(정산!$E$25="O")*정산!$G$9+(정산!$E$10=H$2)*(정산!$F$25="O")*정산!$G$10+(정산!$E$11=H$2)*(정산!$G$25="O")*정산!$G$11+(정산!$E$12=H$2)*(정산!$H$25="O")*정산!$G$12) -> 0 | I11: =IF(OR($A11=0,I$2=0,$A11=I$2),0,(정산!$E$7=I$2)*(정산!$C$25="O")*정산!$G$7+(정산!$E$8=I$2)*(정산!$D$25="O")*정산!$G$8+(정산!$E$9=I$2)*(정산!$E$25="O")*정산!$G$9+(정산!$E$10=I$2)*(정산!$F$25="O")*정산!$G$10+(정산!$E$11=I$2)*(정산!$G$25="O")*정산!$G$11+(정산!$E$12=I$2)*(정산!$H$25="O")*정산!$G$12) -> 0 | ... M11: =IF(OR($A11=0,M$2=0,$A11=M$2),0,(정산!$E$7=M$2)*(정산!$C$25="O")*정산!$G$7+(정산!$E$8=M$2)*(정산!$D$25="O")*정산!$G$8+(정산!$E$9=M$2)*(정산!$E$25="O")*정산!$G$9+(정산!$E$10=M$2)*(정산!$F$25="O")*정산!$G$10+(정산!$E$11=M$2)*(정산!$G$25="O")*정산!$G$11+(정산!$E$12=M$2)*(정산!$H$25="O")*정산!$G$12) -> 0
A12: =정산!B26 -> 0 | B12: =IF(OR($A12=0,B$2=0,$A12=B$2),0,(정산!$E$7=B$2)*(정산!$C$26="O")*정산!$G$7+(정산!$E$8=B$2)*(정산!$D$26="O")*정산!$G$8+(정산!$E$9=B$2)*(정산!$E$26="O")*정산!$G$9+(정산!$E$10=B$2)*(정산!$F$26="O")*정산!$G$10+(정산!$E$11=B$2)*(정산!$G$26="O")*정산!$G$11+(정산!$E$12=B$2)*(정산!$H$26="O")*정산!$G$12) -> 0 | C12: =IF(OR($A12=0,C$2=0,$A12=C$2),0,(정산!$E$7=C$2)*(정산!$C$26="O")*정산!$G$7+(정산!$E$8=C$2)*(정산!$D$26="O")*정산!$G$8+(정산!$E$9=C$2)*(정산!$E$26="O")*정산!$G$9+(정산!$E$10=C$2)*(정산!$F$26="O")*정산!$G$10+(정산!$E$11=C$2)*(정산!$G$26="O")*정산!$G$11+(정산!$E$12=C$2)*(정산!$H$26="O")*정산!$G$12) -> 0 | D12: =IF(OR($A12=0,D$2=0,$A12=D$2),0,(정산!$E$7=D$2)*(정산!$C$26="O")*정산!$G$7+(정산!$E$8=D$2)*(정산!$D$26="O")*정산!$G$8+(정산!$E$9=D$2)*(정산!$E$26="O")*정산!$G$9+(정산!$E$10=D$2)*(정산!$F$26="O")*정산!$G$10+(정산!$E$11=D$2)*(정산!$G$26="O")*정산!$G$11+(정산!$E$12=D$2)*(정산!$H$26="O")*정산!$G$12) -> 0 | E12: =IF(OR($A12=0,E$2=0,$A12=E$2),0,(정산!$E$7=E$2)*(정산!$C$26="O")*정산!$G$7+(정산!$E$8=E$2)*(정산!$D$26="O")*정산!$G$8+(정산!$E$9=E$2)*(정산!$E$26="O")*정산!$G$9+(정산!$E$10=E$2)*(정산!$F$26="O")*정산!$G$10+(정산!$E$11=E$2)*(정산!$G$26="O")*정산!$G$11+(정산!$E$12=E$2)*(정산!$H$26="O")*정산!$G$12) -> 0 | F12: =IF(OR($A12=0,F$2=0,$A12=F$2),0,(정산!$E$7=F$2)*(정산!$C$26="O")*정산!$G$7+(정산!$E$8=F$2)*(정산!$D$26="O")*정산!$G$8+(정산!$E$9=F$2)*(정산!$E$26="O")*정산!$G$9+(정산!$E$10=F$2)*(정산!$F$26="O")*정산!$G$10+(정산!$E$11=F$2)*(정산!$G$26="O")*정산!$G$11+(정산!$E$12=F$2)*(정산!$H$26="O")*정산!$G$12) -> 0 | G12: =IF(OR($A12=0,G$2=0,$A12=G$2),0,(정산!$E$7=G$2)*(정산!$C$26="O")*정산!$G$7+(정산!$E$8=G$2)*(정산!$D$26="O")*정산!$G$8+(정산!$E$9=G$2)*(정산!$E$26="O")*정산!$G$9+(정산!$E$10=G$2)*(정산!$F$26="O")*정산!$G$10+(정산!$E$11=G$2)*(정산!$G$26="O")*정산!$G$11+(정산!$E$12=G$2)*(정산!$H$26="O")*정산!$G$12) -> 0 | H12: =IF(OR($A12=0,H$2=0,$A12=H$2),0,(정산!$E$7=H$2)*(정산!$C$26="O")*정산!$G$7+(정산!$E$8=H$2)*(정산!$D$26="O")*정산!$G$8+(정산!$E$9=H$2)*(정산!$E$26="O")*정산!$G$9+(정산!$E$10=H$2)*(정산!$F$26="O")*정산!$G$10+(정산!$E$11=H$2)*(정산!$G$26="O")*정산!$G$11+(정산!$E$12=H$2)*(정산!$H$26="O")*정산!$G$12) -> 0 | I12: =IF(OR($A12=0,I$2=0,$A12=I$2),0,(정산!$E$7=I$2)*(정산!$C$26="O")*정산!$G$7+(정산!$E$8=I$2)*(정산!$D$26="O")*정산!$G$8+(정산!$E$9=I$2)*(정산!$E$26="O")*정산!$G$9+(정산!$E$10=I$2)*(정산!$F$26="O")*정산!$G$10+(정산!$E$11=I$2)*(정산!$G$26="O")*정산!$G$11+(정산!$E$12=I$2)*(정산!$H$26="O")*정산!$G$12) -> 0 | ... M12: =IF(OR($A12=0,M$2=0,$A12=M$2),0,(정산!$E$7=M$2)*(정산!$C$26="O")*정산!$G$7+(정산!$E$8=M$2)*(정산!$D$26="O")*정산!$G$8+(정산!$E$9=M$2)*(정산!$E$26="O")*정산!$G$9+(정산!$E$10=M$2)*(정산!$F$26="O")*정산!$G$10+(정산!$E$11=M$2)*(정산!$G$26="O")*정산!$G$11+(정산!$E$12=M$2)*(정산!$H$26="O")*정산!$G$12) -> 0
A13: =정산!B27 -> 0 | B13: =IF(OR($A13=0,B$2=0,$A13=B$2),0,(정산!$E$7=B$2)*(정산!$C$27="O")*정산!$G$7+(정산!$E$8=B$2)*(정산!$D$27="O")*정산!$G$8+(정산!$E$9=B$2)*(정산!$E$27="O")*정산!$G$9+(정산!$E$10=B$2)*(정산!$F$27="O")*정산!$G$10+(정산!$E$11=B$2)*(정산!$G$27="O")*정산!$G$11+(정산!$E$12=B$2)*(정산!$H$27="O")*정산!$G$12) -> 0 | C13: =IF(OR($A13=0,C$2=0,$A13=C$2),0,(정산!$E$7=C$2)*(정산!$C$27="O")*정산!$G$7+(정산!$E$8=C$2)*(정산!$D$27="O")*정산!$G$8+(정산!$E$9=C$2)*(정산!$E$27="O")*정산!$G$9+(정산!$E$10=C$2)*(정산!$F$27="O")*정산!$G$10+(정산!$E$11=C$2)*(정산!$G$27="O")*정산!$G$11+(정산!$E$12=C$2)*(정산!$H$27="O")*정산!$G$12) -> 0 | D13: =IF(OR($A13=0,D$2=0,$A13=D$2),0,(정산!$E$7=D$2)*(정산!$C$27="O")*정산!$G$7+(정산!$E$8=D$2)*(정산!$D$27="O")*정산!$G$8+(정산!$E$9=D$2)*(정산!$E$27="O")*정산!$G$9+(정산!$E$10=D$2)*(정산!$F$27="O")*정산!$G$10+(정산!$E$11=D$2)*(정산!$G$27="O")*정산!$G$11+(정산!$E$12=D$2)*(정산!$H$27="O")*정산!$G$12) -> 0 | E13: =IF(OR($A13=0,E$2=0,$A13=E$2),0,(정산!$E$7=E$2)*(정산!$C$27="O")*정산!$G$7+(정산!$E$8=E$2)*(정산!$D$27="O")*정산!$G$8+(정산!$E$9=E$2)*(정산!$E$27="O")*정산!$G$9+(정산!$E$10=E$2)*(정산!$F$27="O")*정산!$G$10+(정산!$E$11=E$2)*(정산!$G$27="O")*정산!$G$11+(정산!$E$12=E$2)*(정산!$H$27="O")*정산!$G$12) -> 0 | F13: =IF(OR($A13=0,F$2=0,$A13=F$2),0,(정산!$E$7=F$2)*(정산!$C$27="O")*정산!$G$7+(정산!$E$8=F$2)*(정산!$D$27="O")*정산!$G$8+(정산!$E$9=F$2)*(정산!$E$27="O")*정산!$G$9+(정산!$E$10=F$2)*(정산!$F$27="O")*정산!$G$10+(정산!$E$11=F$2)*(정산!$G$27="O")*정산!$G$11+(정산!$E$12=F$2)*(정산!$H$27="O")*정산!$G$12) -> 0 | G13: =IF(OR($A13=0,G$2=0,$A13=G$2),0,(정산!$E$7=G$2)*(정산!$C$27="O")*정산!$G$7+(정산!$E$8=G$2)*(정산!$D$27="O")*정산!$G$8+(정산!$E$9=G$2)*(정산!$E$27="O")*정산!$G$9+(정산!$E$10=G$2)*(정산!$F$27="O")*정산!$G$10+(정산!$E$11=G$2)*(정산!$G$27="O")*정산!$G$11+(정산!$E$12=G$2)*(정산!$H$27="O")*정산!$G$12) -> 0 | H13: =IF(OR($A13=0,H$2=0,$A13=H$2),0,(정산!$E$7=H$2)*(정산!$C$27="O")*정산!$G$7+(정산!$E$8=H$2)*(정산!$D$27="O")*정산!$G$8+(정산!$E$9=H$2)*(정산!$E$27="O")*정산!$G$9+(정산!$E$10=H$2)*(정산!$F$27="O")*정산!$G$10+(정산!$E$11=H$2)*(정산!$G$27="O")*정산!$G$11+(정산!$E$12=H$2)*(정산!$H$27="O")*정산!$G$12) -> 0 | I13: =IF(OR($A13=0,I$2=0,$A13=I$2),0,(정산!$E$7=I$2)*(정산!$C$27="O")*정산!$G$7+(정산!$E$8=I$2)*(정산!$D$27="O")*정산!$G$8+(정산!$E$9=I$2)*(정산!$E$27="O")*정산!$G$9+(정산!$E$10=I$2)*(정산!$F$27="O")*정산!$G$10+(정산!$E$11=I$2)*(정산!$G$27="O")*정산!$G$11+(정산!$E$12=I$2)*(정산!$H$27="O")*정산!$G$12) -> 0 | ... M13: =IF(OR($A13=0,M$2=0,$A13=M$2),0,(정산!$E$7=M$2)*(정산!$C$27="O")*정산!$G$7+(정산!$E$8=M$2)*(정산!$D$27="O")*정산!$G$8+(정산!$E$9=M$2)*(정산!$E$27="O")*정산!$G$9+(정산!$E$10=M$2)*(정산!$F$27="O")*정산!$G$10+(정산!$E$11=M$2)*(정산!$G$27="O")*정산!$G$11+(정산!$E$12=M$2)*(정산!$H$27="O")*정산!$G$12) -> 0
A14: =정산!B28 -> 0 | B14: =IF(OR($A14=0,B$2=0,$A14=B$2),0,(정산!$E$7=B$2)*(정산!$C$28="O")*정산!$G$7+(정산!$E$8=B$2)*(정산!$D$28="O")*정산!$G$8+(정산!$E$9=B$2)*(정산!$E$28="O")*정산!$G$9+(정산!$E$10=B$2)*(정산!$F$28="O")*정산!$G$10+(정산!$E$11=B$2)*(정산!$G$28="O")*정산!$G$11+(정산!$E$12=B$2)*(정산!$H$28="O")*정산!$G$12) -> 0 | C14: =IF(OR($A14=0,C$2=0,$A14=C$2),0,(정산!$E$7=C$2)*(정산!$C$28="O")*정산!$G$7+(정산!$E$8=C$2)*(정산!$D$28="O")*정산!$G$8+(정산!$E$9=C$2)*(정산!$E$28="O")*정산!$G$9+(정산!$E$10=C$2)*(정산!$F$28="O")*정산!$G$10+(정산!$E$11=C$2)*(정산!$G$28="O")*정산!$G$11+(정산!$E$12=C$2)*(정산!$H$28="O")*정산!$G$12) -> 0 | D14: =IF(OR($A14=0,D$2=0,$A14=D$2),0,(정산!$E$7=D$2)*(정산!$C$28="O")*정산!$G$7+(정산!$E$8=D$2)*(정산!$D$28="O")*정산!$G$8+(정산!$E$9=D$2)*(정산!$E$28="O")*정산!$G$9+(정산!$E$10=D$2)*(정산!$F$28="O")*정산!$G$10+(정산!$E$11=D$2)*(정산!$G$28="O")*정산!$G$11+(정산!$E$12=D$2)*(정산!$H$28="O")*정산!$G$12) -> 0 | E14: =IF(OR($A14=0,E$2=0,$A14=E$2),0,(정산!$E$7=E$2)*(정산!$C$28="O")*정산!$G$7+(정산!$E$8=E$2)*(정산!$D$28="O")*정산!$G$8+(정산!$E$9=E$2)*(정산!$E$28="O")*정산!$G$9+(정산!$E$10=E$2)*(정산!$F$28="O")*정산!$G$10+(정산!$E$11=E$2)*(정산!$G$28="O")*정산!$G$11+(정산!$E$12=E$2)*(정산!$H$28="O")*정산!$G$12) -> 0 | F14: =IF(OR($A14=0,F$2=0,$A14=F$2),0,(정산!$E$7=F$2)*(정산!$C$28="O")*정산!$G$7+(정산!$E$8=F$2)*(정산!$D$28="O")*정산!$G$8+(정산!$E$9=F$2)*(정산!$E$28="O")*정산!$G$9+(정산!$E$10=F$2)*(정산!$F$28="O")*정산!$G$10+(정산!$E$11=F$2)*(정산!$G$28="O")*정산!$G$11+(정산!$E$12=F$2)*(정산!$H$28="O")*정산!$G$12) -> 0 | G14: =IF(OR($A14=0,G$2=0,$A14=G$2),0,(정산!$E$7=G$2)*(정산!$C$28="O")*정산!$G$7+(정산!$E$8=G$2)*(정산!$D$28="O")*정산!$G$8+(정산!$E$9=G$2)*(정산!$E$28="O")*정산!$G$9+(정산!$E$10=G$2)*(정산!$F$28="O")*정산!$G$10+(정산!$E$11=G$2)*(정산!$G$28="O")*정산!$G$11+(정산!$E$12=G$2)*(정산!$H$28="O")*정산!$G$12) -> 0 | H14: =IF(OR($A14=0,H$2=0,$A14=H$2),0,(정산!$E$7=H$2)*(정산!$C$28="O")*정산!$G$7+(정산!$E$8=H$2)*(정산!$D$28="O")*정산!$G$8+(정산!$E$9=H$2)*(정산!$E$28="O")*정산!$G$9+(정산!$E$10=H$2)*(정산!$F$28="O")*정산!$G$10+(정산!$E$11=H$2)*(정산!$G$28="O")*정산!$G$11+(정산!$E$12=H$2)*(정산!$H$28="O")*정산!$G$12) -> 0 | I14: =IF(OR($A14=0,I$2=0,$A14=I$2),0,(정산!$E$7=I$2)*(정산!$C$28="O")*정산!$G$7+(정산!$E$8=I$2)*(정산!$D$28="O")*정산!$G$8+(정산!$E$9=I$2)*(정산!$E$28="O")*정산!$G$9+(정산!$E$10=I$2)*(정산!$F$28="O")*정산!$G$10+(정산!$E$11=I$2)*(정산!$G$28="O")*정산!$G$11+(정산!$E$12=I$2)*(정산!$H$28="O")*정산!$G$12) -> 0 | ... M14: =IF(OR($A14=0,M$2=0,$A14=M$2),0,(정산!$E$7=M$2)*(정산!$C$28="O")*정산!$G$7+(정산!$E$8=M$2)*(정산!$D$28="O")*정산!$G$8+(정산!$E$9=M$2)*(정산!$E$28="O")*정산!$G$9+(정산!$E$10=M$2)*(정산!$F$28="O")*정산!$G$10+(정산!$E$11=M$2)*(정산!$G$28="O")*정산!$G$11+(정산!$E$12=M$2)*(정산!$H$28="O")*정산!$G$12) -> 0
